<?xml version="1.0" encoding="utf-8"?>
<robot
  name="edo_sim" xmlns:xacro="http://ros.org/wiki/xacro">


  <gazebo>
    <plugin name="ros_control" filename="libgazebo_ros_control.so">
      <!--robotNamespace>/edo</robotNamespace-->
      <!--robotSimType>gazebo_ros_control/DefaultRobotHWSim</robotSimType-->
    </plugin>
  </gazebo>

  <link
    name="base_link">
    <inertial>
      <origin
        xyz="0.057188 0.005983 0.05"
        rpy="0 0 0" />
      <mass
        value="0.0785942338762368" />
      <inertia
        ixx="0.0123841200738068"
        ixy="-0.000187984913202787"
        ixz="-1.32683892634308E-06"
        iyy="7.0169034503364E-05"
        iyz="-9.17416945099319E-05"
        izz="0.0123862261905614" />
    </inertial>
    <visual>
      <origin
        xyz="0 0 0"
        rpy="0 0 0" />
      <geometry>
        <mesh
          filename="package://edo_description/meshes/base_link.STL" />
        <material name="LightGrey">
	  <color rgba="0.7 0.7 0.7 1.0"/>
        </material>
      </geometry>
      <material
        name="">
        <color
          rgba="0.792156862745098 0.819607843137255 0.933333333333333 1" />
      </material>
    </visual>
    <collision>
      <origin
        xyz="0 0 0"
        rpy="0 0 0" />
      <geometry>
        <mesh
          filename="package://edo_description/meshes/base_link.STL" />
      </geometry>
    </collision>
  </link>
  <link
    name="link_1">
    <inertial>
      <origin
        xyz="-0.037464 0.047260 0"
        rpy="0 0 0" />
      <mass
        value="0.0785942338762368" />
      <inertia
        ixx="0.0123841200738068"
        ixy="0.000187984913202727"
        ixz="-1.32683892634271E-06"
        iyy="7.01690345033622E-05"
        iyz="9.17416945099368E-05"
        izz="0.0123862261905615" />
    </inertial>
    <visual>
      <origin
        xyz="0 0 0"
        rpy="0 0 0" />
      <geometry>
        <mesh
          filename="package://edo_description/meshes/link_1.STL" />
        <material name="LightGrey">
	  <color rgba="0.7 0.7 0.7 1.0"/>
        </material>
      </geometry>
      <material
        name="">
        <color
          rgba="0.792156862745098 0.819607843137255 0.933333333333333 1" />
      </material>
    </visual>
    <collision>
      <origin
        xyz="0 0 0"
        rpy="0 0 0" />
      <geometry>
        <mesh
          filename="package://edo_description/meshes/link_1.STL" />
      </geometry>
    </collision>
  </link>
  <joint
    name="joint_1"
    type="continuous">
    <origin
      xyz="0.057188 0.0059831 0.13343"
      rpy="1.5708 6.9389E-16 -3.1416" />
    <parent
      link="base_link" />
    <child
      link="link_1" />
    <axis
      xyz="0 1 0" />
    <limit effort="150.0" lower="-6.28318530718" upper="6.28318530718" velocity="3.15"/>
    <dynamics damping="0.0" friction="0.0"/>
  </joint>
  <link
    name="link_2">
    <inertial>
      <origin
        xyz="-0.016423 0.031803 -0.045948"
        rpy="0 0 0" />
      <mass
        value="0.0785942338762368" />
      <inertia
        ixx="0.0122070242873091"
        ixy="0.000930596667670934"
        ixz="-0.0011486325666074"
        iyy="0.007576065624266"
        iyz="0.0059380539105297"
        izz="0.00505742538729646" />
    </inertial>
    <visual>
      <origin
        xyz="0 0 0"
        rpy="0 0 0" />
      <geometry>
        <mesh
          filename="package://edo_description/meshes/link_2.STL" />
        <material name="LightGrey">
	  <color rgba="0.7 0.7 0.7 1.0"/>
        </material>
      </geometry>
      <material
        name="">
        <color
          rgba="0.792156862745098 0.819607843137255 0.933333333333333 1" />
      </material>
    </visual>
    <collision>
      <origin
        xyz="0 0 0"
        rpy="0 0 0" />
      <geometry>
        <mesh
          filename="package://edo_description/meshes/link_2.STL" />
      </geometry>
    </collision>
  </link>
  <joint
    name="joint_2"
    type="continuous">
    <origin
      xyz="0 0.18967 0"
      rpy="0.94237 -0.4634 -0.11653" />
    <parent
      link="link_1" />
    <child
      link="link_2" />
    <axis
      xyz="-0.88847 0.2908 0.35504" />
    <limit effort="150.0" lower="-6.28318530718" upper="6.28318530718" velocity="3.15"/>
    <dynamics damping="0.0" friction="0.0"/>
  </joint>
  <link
    name="link_3">
    <inertial>
      <origin
        xyz="-0.031475 0.013100 0.000326"
        rpy="0 0 0" />
      <mass
        value="0.0785942338762368" />
      <inertia
        ixx="0.0123841200738068"
        ixy="0.000187984913202718"
        ixz="1.32683892634266E-06"
        iyy="7.01690345033619E-05"
        iyz="-9.17416945099381E-05"
        izz="0.0123862261905615" />
    </inertial>
    <visual>
      <origin
        xyz="0 0 0"
        rpy="0 0 0" />
      <geometry>
        <mesh
          filename="package://edo_description/meshes/link_3.STL" />
        <material name="LightGrey">
	  <color rgba="0.7 0.7 0.7 1.0"/>
        </material>
      </geometry>
      <material
        name="">
        <color
          rgba="0.792156862745098 0.819607843137255 0.933333333333333 1" />
      </material>
    </visual>
    <collision>
      <origin
        xyz="0 0 0"
        rpy="0 0 0" />
      <geometry>
        <mesh
          filename="package://edo_description/meshes/link_3.STL" />
      </geometry>
    </collision>
  </link>
  <joint
    name="joint_3"
    type="continuous">
    <origin
      xyz="-0.024558 0.12737 -0.16578"
      rpy="0.97336 -0.36296 2.8253" />
    <parent
      link="link_2" />
    <child
      link="link_3" />
    <axis
      xyz="1 0 0" />
    <limit effort="150.0" lower="-6.28318530718" upper="6.28318530718" velocity="3.15"/>
    <dynamics damping="0.0" friction="0.0"/>
  </joint>
  <link
    name="link_4">
    <inertial>
      <origin
        xyz="0.033909 0.000544 -0.013765"
        rpy="0 0 0" />
      <mass
        value="0.0785942338762368" />
      <inertia
        ixx="0.0123841200738068"
        ixy="-1.32683892634285E-06"
        ixz="0.000187984913202718"
        iyy="0.0123862261905615"
        iyz="9.17416945099506E-05"
        izz="7.01690345033621E-05" />
    </inertial>
    <visual>
      <origin
        xyz="0 0 0"
        rpy="0 0 0" />
      <geometry>
        <mesh
          filename="package://edo_description/meshes/link_4.STL" />
        <material name="LightGrey">
	  <color rgba="0.7 0.7 0.7 1.0"/>
        </material>
      </geometry>
      <material
        name="">
        <color
          rgba="0.792156862745098 0.819607843137255 0.933333333333333 1" />
      </material>
    </visual>
    <collision>
      <origin
        xyz="0 0 0"
        rpy="0 0 0" />
      <geometry>
        <mesh
          filename="package://edo_description/meshes/link_4.STL" />
      </geometry>
    </collision>
  </link>
  <joint
    name="joint_4"
    type="continuous">
    <origin
      xyz="0.0088 -0.1588 0"
      rpy="-1.5708 0 0" />
    <parent
      link="link_3" />
    <child
      link="link_4" />
    <axis
      xyz="0 0 -1" />
    <limit effort="150.0" lower="-6.28318530718" upper="6.28318530718" velocity="3.15"/>
    <dynamics damping="0.0" friction="0.0"/>
  </joint>
  <link
    name="link_5">
    <inertial>
      <origin
        xyz="0.029485 -0.000458 0.026739"
        rpy="0 0 0" />
      <mass
        value="0.0785942338762368" />
      <inertia
        ixx="0.0123841200738068"
        ixy="1.32683892634191E-06"
        ixz="0.000187984913202582"
        iyy="0.0123862261905615"
        iyz="-9.17416945099552E-05"
        izz="7.01690345033581E-05" />
    </inertial>
    <visual>
      <origin
        xyz="0 0 0"
        rpy="0 0 0" />
      <geometry>
        <mesh
          filename="package://edo_description/meshes/link_5.STL" />
        <material name="LightGrey">
	  <color rgba="0.7 0.7 0.7 1.0"/>
        </material>
      </geometry>
      <material
        name="">
        <color
          rgba="0.792156862745098 0.819607843137255 0.933333333333333 1" />
      </material>
    </visual>
    <collision>
      <origin
        xyz="0 0 0"
        rpy="0 0 0" />
      <geometry>
        <mesh
          filename="package://edo_description/meshes/link_5.STL" />
      </geometry>
    </collision>
  </link>
  <joint
    name="joint_5"
    type="continuous">
    <origin
      xyz="0 0 -0.1053"
      rpy="3.1416 1.1102E-14 3.1416" />
    <parent
      link="link_4" />
    <child
      link="link_5" />
    <axis
      xyz="-1 0 0" />
    <limit effort="150.0" lower="-6.28318530718" upper="6.28318530718" velocity="3.15"/>
    <dynamics damping="0.0" friction="0.0"/>
  </joint>
  <link
    name="link_6">
    <inertial>
      <origin
        xyz="0.000007 -0.009327 0.000006"
        rpy="0 0 0" />
      <mass
        value="0.0279702497322662" />
      <inertia
        ixx="7.63464744598253E-06"
        ixy="1.89204959067221E-10"
        ixz="5.32970316039599E-09"
        iyy="1.45744912344428E-05"
        iyz="1.08958003890421E-10"
        izz="7.62871791498103E-06" />
    </inertial>
    <visual>
      <origin
        xyz="0 0 0"
        rpy="0 0 0" />
      <geometry>
        <mesh
          filename="package://edo_description/meshes/link_6.STL" />
        <material name="LightGrey">
	  <color rgba="0.7 0.7 0.7 1.0"/>
        </material>
      </geometry>
      <material
        name="">
        <color
          rgba="0.792156862745098 0.819607843137255 0.933333333333333 1" />
      </material>
    </visual>
    <collision>
      <origin
        xyz="0 0 0"
        rpy="0 0 0" />
      <geometry>
        <mesh
          filename="package://edo_description/meshes/link_6.STL" />
      </geometry>
    </collision>
  </link>
  <joint
    name="joint_6"
    type="continuous">
    <origin
      xyz="-0.0039 0 0.1636"
      rpy="-1.5708 1.249E-14 0" />
    <parent
      link="link_5" />
    <child
      link="link_6" />
    <axis
      xyz="0 -1 0" />
    <limit effort="150.0" lower="-6.28318530718" upper="6.28318530718" velocity="3.15"/>
    <dynamics damping="0.0" friction="0.0"/>
  </joint>

  <joint name="ee_fixed_joint" type="fixed">
    <parent link="link_6"/>
    <child link="ee_link"/>
    <origin rpy="0.0 0.0 1.57079632679" xyz="0.0 0.0823 0.0"/>
  </joint>
  <link name="ee_link">
    <collision>
      <geometry>
        <box size="0.01 0.01 0.01"/>
      </geometry>
      <origin rpy="0 0 0" xyz="-0.01 0 0"/>
    </collision>
  </link>


  <transmission name="joint_1_trans">
    <type>transmission_interface/SimpleTransmission</type>
    <joint name="joint_1">
      <hardwareInterface>hardware_interface/PositionJointInterface</hardwareInterface>
    </joint>
    <actuator name="joint_1_motor">
      <mechanicalReduction>1</mechanicalReduction>
    </actuator>
  </transmission>
  <transmission name="joint_2_trans">
    <type>transmission_interface/SimpleTransmission</type>
    <joint name="joint_2">
      <hardwareInterface>hardware_interface/PositionJointInterface</hardwareInterface>
    </joint>
    <actuator name="joint_2_motor">
      <mechanicalReduction>1</mechanicalReduction>
    </actuator>
  </transmission>
  <transmission name="joint_3_trans">
    <type>transmission_interface/SimpleTransmission</type>
    <joint name="joint_3">
      <hardwareInterface>hardware_interface/PositionJointInterface</hardwareInterface>
    </joint>
    <actuator name="joint_3_motor">
      <mechanicalReduction>1</mechanicalReduction>
    </actuator>
  </transmission>
  <transmission name="joint_4_trans">
    <type>transmission_interface/SimpleTransmission</type>
    <joint name="joint_4">
      <hardwareInterface>hardware_interface/PositionJointInterface</hardwareInterface>
    </joint>
    <actuator name="joint_4_motor">
      <mechanicalReduction>1</mechanicalReduction>
    </actuator>
  </transmission>
  <transmission name="joint_5_trans">
    <type>transmission_interface/SimpleTransmission</type>
    <joint name="joint_5">
      <hardwareInterface>hardware_interface/PositionJointInterface</hardwareInterface>
    </joint>
    <actuator name="joint_5_motor">
      <mechanicalReduction>1</mechanicalReduction>
    </actuator>
  </transmission>
  <transmission name="joint_6_trans">
    <type>transmission_interface/SimpleTransmission</type>
    <joint name="joint_6">
      <hardwareInterface>hardware_interface/PositionJointInterface</hardwareInterface>
    </joint>
    <actuator name="joint_6_motor">
      <mechanicalReduction>1</mechanicalReduction>
    </actuator>
  </transmission>

  <gazebo reference="link_1">
    <selfCollide>true</selfCollide>
  </gazebo>
  <gazebo reference="link_2">
    <selfCollide>true</selfCollide>
  </gazebo>
  <gazebo reference="link_3">
    <selfCollide>true</selfCollide>
  </gazebo>
  <gazebo reference="link_4">
    <selfCollide>true</selfCollide>
  </gazebo>
  <gazebo reference="link_5">
    <selfCollide>true</selfCollide>
  </gazebo>
  <gazebo reference="link_6">
    <selfCollide>true</selfCollide>
  </gazebo>



  <!-- ROS base_link to UR 'Base' Coordinates transform -->
  <!--link name="map"/>
  <joint name="base-map_fixed_joint" type="fixed"-->
    <!-- NOTE: this rotation is only needed as long as base_link itself is
                 not corrected wrt the real robot (ie: rotated over 180
                 degrees)
      -->
    <!--origin rpy="0 0 0" xyz="0 0 0"/>
    <parent link="map"/>
    <child link="base_link"/>
  </joint-->

  <!-- ROS base_link to UR 'Base' Coordinates transform -->
  <!--link name="base"/>
  <joint name="base_link-base_fixed_joint" type="fixed"-->
    <!-- NOTE: this rotation is only needed as long as base_link itself is
                 not corrected wrt the real robot (ie: rotated over 180
                 degrees)
      -->
    <!--origin rpy="0 0 -3.14159265359" xyz="0 0 0"/>
    <parent link="base_link"/>
    <child link="base"/>
  </joint-->

<!-- Frame coincident with all-zeros TCP on UR controller -->
  <link name="tool0"/>
  <joint name="link_6-tool0_fixed_joint" type="fixed">
    <origin rpy="-1.57079632679 0 0" xyz="0 0.0823 0"/>
    <parent link="link_6"/>
    <child link="tool0"/>
  </joint>
  <link name="world"/>
  <joint name="world_joint" type="fixed">
    <parent link="world"/>
    <child link="base_link"/>
    <origin rpy="0.0 0.0 0.0" xyz="0.0 0.0 0.0"/>
  </joint>
</robot>
